Workbook

Sheet はじめに
B2: AIと宿｜お願い文集
B3: 宿で働く人のための、コピペで使えるAIへの「お願い文」集です。ChatGPT・Gemini・Claudeのどれでも使えます。
B5: ■ 使い方は3ステップ
B6: ① 「①宿プロフィール」シートの黄色いところを、自分の宿に書き換えます（1回だけ・1分）。
B7: ② 「②困りごとから探す」シートで、今困っていることの行を見つけます。
B8: ③ 「AIに送る文（お願い文）」のセルをコピーして、AIに貼り付けて送ります。
B9: 文の中の【 】や（例：…）の部分は、自分の内容に書き換えてから送ってください。
B10: ④ AIの答えが出たら、同じ行の「確認すること」を見てから使います。
B12: ■ 「お願い文」とは？
B13: AIに送る文章のひな形のことです。そのままコピーして貼れば、AIが宿の仕事を手伝ってくれます。
B15: ■ シートの違い（どれを使えばいい？）
B16: ・①宿プロフィール … 最初に1回だけ。宿の情報を入れます。
... B37: AIと宿のサイトの記事で、1つずつ解説しています。各行の「読む記事」に記事名があります。

Sheet ①宿プロフィール
B1: 宿プロフィール（最初に1回だけ書き換えます）
B2: 黄色いセルを、自分の宿の内容に書き換えてください。いまの文字は「例」です。書き換えると、すべてのお願い文に自動で反映されます。
B3: 項目 | C3: ここに書く（黄色） | D3: 書き方の例 | E3: 自動（触らない）
B4: 宿の種類 | C4: 温泉旅館 | D4: 旅館／温泉旅館／ホテル／民宿 など | E4: =IF(TRIM(C4&"")="","【"&B4&"を入力】",TRIM(C4&"")) -> 温泉旅館
B5: あなたの立場 | C5: 女将 | D5: 女将／支配人／オーナー／フロント担当／スタッフ など | E5: =IF(TRIM(C5&"")="","【"&B5&"を入力】",TRIM(C5&"")) -> 女将
B6: 客室数（数字だけ） | C6: 12 | D6: 例：12 | E6: =IF(TRIM(C6&"")="","【"&B6&"を入力】",TRIM(C6&"")) -> 12
B7: 主なお客様 | C7: ご夫婦・ご家族 | D7: 例：ご夫婦／ご家族／外国人旅行者／ビジネス出張 | E7: =IF(TRIM(C7&"")="","【"&B7&"を入力】",TRIM(C7&"")) -> ご夫婦・ご家族
B8: 場所（地域） | C8: 山あいの温泉地 | D8: 例：海沿いの町／駅前／山あいの温泉地 | E8: =IF(TRIM(C8&"")="","【"&B8&"を入力】",TRIM(C8&"")) -> 山あいの温泉地
B9: 宿の特徴（ひとこと） | C9: 夕食の地元食材と、静かな夜が自慢 | D9: 例：景色／食事／温泉／おもてなし | E9: =IF(TRIM(C9&"")="","【"&B9&"を入力】",TRIM(C9&"")) -> 夕食の地元食材と、静かな夜が自慢
B10: 文章の口調 | C10: 丁寧であたたかい | D10: 例：丁寧であたたかい／簡潔／格式高く | E10: =IF(TRIM(C10&"")="","【"&B10&"を入力】",TRIM(C10&"")) -> 丁寧であたたかい
B12: お願い文の先頭に自己紹介を付ける | C12: いいえ | D12: 「はい」にすると、全部のお願い文の先頭に下の自己紹介が付きます
B14: 自己紹介文（自動で完成） | C14: ="私は"&E8&"の"&E4&"で、"&E5&"として働いています。客室は"&E6&"室ほどで、お客様は主に"&E7&"です。宿の特徴は、"&E9&"。文章の口調は「"&E10&"」でお願いします。" -> 私は山あいの温泉地の温泉旅館で、女将として働いています。客室は12室ほどで、お客様は主にご夫婦・ご家族です。宿の特徴は、夕食の地元食材と、静かな夜が自慢。文章の口調は「丁寧であたたかい」でお願いします。
B15: AIとの会話の最初に、この文を1回貼ると、宿の前提が伝わります（コピーして使います）。
B17: ※ ここには、お客様の名前・電話番号・予約番号などの個人情報や、社内の秘密は書かないでください。

Sheet ②困りごとから探す
A1: 【このシートの使い方】今、困っていることから探すシートです。迷ったら、まずここを使います。 ①自分の困りごとの行を見つける ②「AIに送る文」のセルをコピーする ③AIに貼り付ける（【 】や（例：…）は自分の内容に書き換える） ④答えが出たら、同じ行の「確認すること」を見る。（全24件）
A2: No | B2: 困りごとの分類 | C2: 今の困りごと | D2: AIに送る文（お願い文） ← ここをコピー | E2: 確認すること | F2: まず読む記事 | G2: その次に読む記事
A3: 1 | B3: AIを始めたい | C3: AIを始めたいけど、何をすればいいかわからない | D3: =IF(①宿プロフィール!$C$12="はい",①宿プロフィール!$C$14&CHAR(10)&CHAR(10),"")&SUBSTITUTE(SUBSTITUTE(SUBSTITUTE(I3,"{{宿の種類}}",①宿プロフィール!$E$4),"{{立場}}",①宿プロフィール!$E$5),"{{客室数}}",①宿プロフィール!$E$6) -> 私は温泉旅館で働いています。 AIをこれから仕事で使い始めたいのですが、何から始めればいいかわかりません。 まず私に、宿で働く人がAIを使い始める手順を教えてください。 ・全部で3段階くらいに絞って ・ITが苦手でも迷わない言葉で ・最初の一歩だけ、今日できることにしてください | E3: ✔ 3段階の手順のうち、今日できる一歩を1つ決めた ✔ 個人情報（お客様の名前・電話・メール・予約番号）は入れていない（A様のように置き換える） | F3: ・AIってそもそも何？宿の仕事のことだけ、やさしく説明 | G3: ・ChatGPT・Gemini・Claudeって何が違う？迷ったらどれを使う？ ・ChatGPTを始めてみよう。登録からはじめての質問まで ・AIを使うときに知っておきたいこと【個人情報・確認の基本】 | I3: 私は{{宿の種類}}で働いています。 AIをこれから仕事で使い始めたいのですが、何から始めればいいかわかりません。 まず私に、宿で働く人がAIを使い始める手順を教えてください。 ・全部で3段階くらいに絞って ・ITが苦手でも迷わない言葉で ・最初の一歩だけ、今日できることにしてください
A4: 2 | B4: AIを始めたい | C4: ChatGPTを使ってみたい | D4: =IF(①宿プロフィール!$C$12="はい",①宿プロフィール!$C$14&CHAR(10)&CHAR(10),"")&SUBSTITUTE(SUBSTITUTE(SUBSTITUTE(I4,"{{宿の種類}}",①宿プロフィール!$E$4),"{{立場}}",①宿プロフィール!$E$5),"{{客室数}}",①宿プロフィール!$E$6) -> はじめまして。私は温泉旅館で働いています。 ChatGPTを使うのは、今日が初めてです。 宿の仕事（予約・接客・文章書き）で、 あなたに手伝ってもらえることを3つだけ、 今日から試せる形で教えてください。 | E4: ✔ AIが挙げた3つのうち、今日試すものを1つだけ選んだ ✔ 個人情報（お客様の名前・電話・メール・予約番号）は入れていない（A様のように置き換える） | F4: ・ChatGPTを始めてみよう。登録からはじめての質問まで | G4: ・Geminiを始めてみよう。Googleアカウントがあればすぐ使える ・Claudeを始めてみよう。丁寧な日本語に定評のあるAI ・AIに質問してみよう。送る→読む→深掘りの練習 | I4: はじめまして。私は{{宿の種類}}で働いています。 ChatGPTを使うのは、今日が初めてです。 宿の仕事（予約・接客・文章書き）で、 あなたに手伝ってもらえることを3つだけ、 今日から試せる形で教えてください。
A5: 3 | B5: AIを始めたい | C5: AIに何を聞けばいいかわからない | D5: =IF(①宿プロフィール!$C$12="はい",①宿プロフィール!$C$14&CHAR(10)&CHAR(10),"")&SUBSTITUTE(SUBSTITUTE(SUBSTITUTE(I5,"{{宿の種類}}",①宿プロフィール!$E$4),"{{立場}}",①宿プロフィール!$E$5),"{{客室数}}",①宿プロフィール!$E$6) -> 私は宿で働いています。AIを使い始めたばかりで、 正直「何を聞けばいいか」がわかりません。 宿の仕事であなたに聞けることを、 「教えて」「作って」「一緒に考えて」の3つに分けて、 それぞれ今日試せる質問文を2つずつ教えてください。 | E5: ✔ 出てきた質問文を、1つ実際にAIへ送ってみた ✔ 個人情報（お客様の名前・電話・メール・予約番号）は入れていない（A様のように置き換える） | F5: ・AIには何を聞けばいい？宿の仕事で使える質問カタログ | G5: ・AIに質問してみよう。送る→読む→深掘りの練習 ・「もう少し詳しく」とAIに聞こう。会話を深める5つのフレーズ ・AIに自分の宿を説明してみよう。背景を伝えると答えが変わる | I5: 私は宿で働いています。AIを使い始めたばかりで、 正直「何を聞けばいいか」がわかりません。 宿の仕事であなたに聞けることを、 「教えて」「作って」「一緒に考えて」の3つに分けて、 それぞれ今日試せる質問文を2つずつ教えてください。
A6: 4 | B6: 仕事を楽にしたい | C6: メールを書くのが面倒 | D6: =IF(①宿プロフィール!$C$12="はい",①宿プロフィール!$C$14&CHAR(10)&CHAR(10),"")&SUBSTITUTE(SUBSTITUTE(SUBSTITUTE(I6,"{{宿の種類}}",①宿プロフィール!$E$4),"{{立場}}",①宿プロフィール!$E$5),"{{客室数}}",①宿プロフィール!$E$6) -> あなたは温泉旅館の女将として お客様へのメール文を書いてください。 ・相手：（例：本日チェックアウトしたお客様） ・目的：（例：宿泊のお礼） ・長さ：200字程度 ・口調：丁寧であたたかい 文面だけお願いします。 | E6: ✔ 宛名・日付・金額・時間が合っている ✔ 送る前に最後まで自分で読んだ ✔ 個人情報（お客様の名前・電話・メール・予約番号）は入れていない（A様のように置き換える） | F6: ・AIにメールを書いてもらう。まずは「お礼メール」から | G6: ・お客様へのメールをAIに手伝ってもらう【実務編】 ・AIに口コミ返信を考えてもらう。感謝と誠意を、早く・気持ちよく ・長い文章を要約してもらう。資料・メール・マニュアルを一瞬で把握 | I6: あなたは{{宿の種類}}の{{立場}}として お客様へのメール文を書いてください。 ・相手：（例：本日チェックアウトしたお客様） ・目的：（例：宿泊のお礼） ・長さ：200字程度 ・口調：丁寧であたたかい 文面だけお願いします。
A7: 5 | B7: 仕事を楽にしたい | C7: 長い資料・文章を読むのがつらい | D7: =IF(①宿プロフィール!$C$12="はい",①宿プロフィール!$C$14&CHAR(10)&CHAR(10),"")&SUBSTITUTE(SUBSTITUTE(SUBSTITUTE(I7,"{{宿の種類}}",①宿プロフィール!$E$4),"{{立場}}",①宿プロフィール!$E$5),"{{客室数}}",①宿プロフィール!$E$6) -> 以下の文書について、まず「構造」を教えてください。 ・これは何についての文書か ・私が読むべき部分はどこか（優先度つきで） ・要点を3行で 【文書】 （ここに読みたい文書を貼り付け） | E7: ✔ 要約は「読むかどうかの判断」まで。大事な決定は原文で確認する ✔ 個人情報（お客様の名前・電話・メール・予約番号）は入れていない（A様のように置き換える） | F7: ・長い文章を要約してもらう。資料・メール・マニュアルを一瞬で把握 | G7: ・会議をAIに整理してもらう。メモと議事録から「決まったこと」だけ ・マニュアルをAIと作る。「口伝」を「形に」するための手順 ・今日の仕事をAIと整理する。朝5分の「今日の予報」 | I7: 以下の文書について、まず「構造」を教えてください。 ・これは何についての文書か ・私が読むべき部分はどこか（優先度つきで） ・要点を3行で 【文書】 （ここに読みたい文書を貼り付け）
A8: 6 | B8: 仕事を楽にしたい | C8: 忙しさの中で、仕事を楽にしたい | D8: =IF(①宿プロフィール!$C$12="はい",①宿プロフィール!$C$14&CHAR(10)&CHAR(10),"")&SUBSTITUTE(SUBSTITUTE(SUBSTITUTE(I8,"{{宿の種類}}",①宿プロフィール!$E$4),"{{立場}}",①宿プロフィール!$E$5),"{{客室数}}",①宿プロフィール!$E$6) -> 朝の5分整理です。今日のタスクをすべて話します。 【今日のタスク（そのまま挙げる）】 ・（例：予約確認2件／A様への連絡／発注／会議準備…） お願い： ・「今日必須／できれば／後回し／人に頼める」に分類 ・「今日必須」3つに、時間の目安を添えて | E8: ✔ 「今日必須」の3つが本当に今日必要か、自分で見直した ✔ 個人情報（お客様の名前・電話・メール・予約番号）は入れていない（A様のように置き換える） | F8: ・今日の仕事をAIと整理する。朝5分の「今日の予報」 | G8: ・会議をAIに整理してもらう。メモと議事録から「決まったこと」だけ ・頭の中のモヤモヤをAIに整理してもらう ・来月やることをAIと整理する。月次の5分レビュー | I8: 朝の5分整理です。今日のタスクをすべて話します。 【今日のタスク（そのまま挙げる）】 ・（例：予約確認2件／A様への連絡／発注／会議準備…） お願い： ・「今日必須／できれば／後回し／人に頼める」に分類 ・「今日必須」3つに、時間の目安を添えて
A9: 7 | B9: お客様対応に困っている | C9: 口コミ返信を考えるのが大変 | D9: =IF(①宿プロフィール!$C$12="はい",①宿プロフィール!$C$14&CHAR(10)&CHAR(10),"")&SUBSTITUTE(SUBSTITUTE(SUBSTITUTE(I9,"{{宿の種類}}",①宿プロフィール!$E$4),"{{立場}}",①宿プロフィール!$E$5),"{{客室数}}",①宿プロフィール!$E$6) -> 私は温泉旅館の女将です。口コミへの返信文を作ってください。 口コミの要点： ・（例：夕食の地元食材がおいしかった） ・（例：スタッフの対応が丁寧だった） 条件： ・長さ150字前後・感謝が伝わるあたたかい口調 ・定型文っぽくしない 文面のみお願いします。 | E9: ✔ お客様が特定できる情報（部屋・日付・人数・同伴者）を書いていない ✔ 返信は公開される。送る前に自分で読む。厳しい口コミは責任者にも見てもらう ✔ 個人情報（お客様の名前・電話・メール・予約番号）は入れていない（A様のように置き換える） | F9: ・AIに口コミ返信を考えてもらう。感謝と誠意を、早く・気持ちよく | G9: ・OTAの口コミをAIに分析してもらう。手順と読み解き方 ・口コミから自分の宿の強みを探す。“当たり前”を武器に変える ・お客様へのメールをAIに手伝ってもらう【実務編】 | I9: 私は{{宿の種類}}の{{立場}}です。口コミへの返信文を作ってください。 口コミの要点： ・（例：夕食の地元食材がおいしかった） ・（例：スタッフの対応が丁寧だった） 条件： ・長さ150字前後・感謝が伝わるあたたかい口調 ・定型文っぽくしない 文面のみお願いします。
A10: 8 | B10: お客様対応に困っている | C10: 同じ問い合わせが来て、対応しきれない | D10: =IF(①宿プロフィール!$C$12="はい",①宿プロフィール!$C$14&CHAR(10)&CHAR(10),"")&SUBSTITUTE(SUBSTITUTE(SUBSTITUTE(I10,"{{宿の種類}}",①宿プロフィール!$E$4),"{{立場}}",①宿プロフィール!$E$5),"{{客室数}}",①宿プロフィール!$E$6) -> 私は宿のフロント担当です。 よくある問い合わせへの「対応メモ」を表にしてください。 よくある質問： 1. （例：チェックイン時間は？） 2. （例：送迎はある？） （実際の質問を挙げる） 表の列：質問／まず答える一文（丁寧な表現で）／確認すべきこと | E10: ✔ 答えの内容（時間・料金・送迎の有無）が実際と合っている ✔ 電話で言えるか、声に出して確かめた ✔ 個人情報（お客様の名前・電話・メール・予約番号）は入れていない（A様のように置き換える） | F10: ・よくある質問（FAQ）をAIと作る。電話を減らし、予約を増やす準備 | G10: ・電話・問い合わせ対応を整理する。「何と答える？」の蓄積をAIと ・館内案内をわかりやすくする。質問が減る案内文の整え方 ・外国人のお客様への案内を考える。やさしい日本語と翻訳の段取り | I10: 私は宿のフロント担当です。 よくある問い合わせへの「対応メモ」を表にしてください。 よくある質問： 1. （例：チェックイン時間は？） 2. （例：送迎はある？） （実際の質問を挙げる） 表の列：質問／まず答える一文（丁寧な表現で）／確認すべきこと
A11: 9 | B11: OTAに困っている | C11: OTAの売上が伸びない | D11: =IF(①宿プロフィール!$C$12="はい",①宿プロフィール!$C$14&CHAR(10)&CHAR(10),"")&SUBSTITUTE(SUBSTITUTE(SUBSTITUTE(I11,"{{宿の種類}}",①宿プロフィール!$E$4),"{{立場}}",①宿プロフィール!$E$5),"{{客室数}}",①宿プロフィール!$E$6) -> 私は宿のOTA運用担当です。 OTAの売上が伸び悩んでいて、何から確認すればいいか整理したいです。 まず、私の宿について質問してください。 一度に質問するのは3つまでにしてください。 質問してほしい観点の例： ・客室数・エリア・客単価の感覚 ・主なOTAと販売するプランの構成 ・最近の予約の動きの感覚 ・いま改善しようとしてきたこと 私が答えたら、次の質問をしてください。 最後に「考えられる原因の整理」と「まず確認したほうがいいこと」を まとめてください。 | E11: ✔ AIの質問に答える。分からない所は「未確認」でよい ✔ 出てきた原因は仮説。実際の数字で確かめる ✔ 個人情報（お客様の名前・電話・メール・予約番号）は入れていない（A様のように置き換える） | F11: ・OTAの宿泊プランをAIと考える。まず全体を整理してから | G11: ・「なぜこのプランが売れない？」をAIと考える ・プラン名を改善する。検索され、選ばれる名前のルール ・OTAの口コミをAIに分析してもらう。手順と読み解き方 | I11: 私は宿のOTA運用担当です。 OTAの売上が伸び悩んでいて、何から確認すればいいか整理したいです。 まず、私の宿について質問してください。 一度に質問するのは3つまでにしてください。 質問してほしい観点の例： ・客室数・エリア・客単価の感覚 ・主なOTAと販売するプランの構成 ・最近の予約の動きの感覚 ・いま改善しようとしてきたこと 私が答えたら、次の質問をしてください。 最後に「考えられる原因の整理」と「まず確認したほうがいいこと」を まとめてください。
A12: 10 | B12: OTAに困っている | C12: OTAの宿泊プラン文章を改善したい | D12: =IF(①宿プロフィール!$C$12="はい",①宿プロフィール!$C$14&CHAR(10)&CHAR(10),"")&SUBSTITUTE(SUBSTITUTE(SUBSTITUTE(I12,"{{宿の種類}}",①宿プロフィール!$E$4),"{{立場}}",①宿プロフィール!$E$5),"{{客室数}}",①宿プロフィール!$E$6) -> 私は宿のOTA担当です。 以下のプラン説明文を改善してください。 【現在の文】 （ここに現在の説明文を貼り付け） お願い： 1. 良いところを2点指摘（そこは残す） 2. 「誰に→何が→どううれしい」の骨格で改善版を提示 3. 「条件・注意」は末尾に分離 4. 200字程度、あたたかい口調で | E12: ✔ 「最安値」「日本一」「必ず」など根拠のない言い切りが入っていない ✔ 料金・特典・条件が、管理画面の実際の内容と合っている ✔ 個人情報（お客様の名前・電話・メール・予約番号）は入れていない（A様のように置き換える） | F12: ・プラン説明を改善する。読まれる文の「型」と注意点 | G12: ・プラン名を改善する。検索され、選ばれる名前のルール ・AIに宿泊プランの文章を作ってもらう。“売れる予感”のある文の骨格 ・OTAの宿泊プランをAIと考える。まず全体を整理してから | I12: 私は宿のOTA担当です。 以下のプラン説明文を改善してください。 【現在の文】 （ここに現在の説明文を貼り付け） お願い： 1. 良いところを2点指摘（そこは残す） 2. 「誰に→何が→どううれしい」の骨格で改善版を提示 3. 「条件・注意」は末尾に分離 4. 200字程度、あたたかい口調で
A13: 11 | B13: OTAに困っている | C13: 作ったプランが、まったく売れない | D13: =IF(①宿プロフィール!$C$12="はい",①宿プロフィール!$C$14&CHAR(10)&CHAR(10),"")&SUBSTITUTE(SUBSTITUTE(SUBSTITUTE(I13,"{{宿の種類}}",①宿プロフィール!$E$4),"{{立場}}",①宿プロフィール!$E$5),"{{客室数}}",①宿プロフィール!$E$6) -> 私は宿のOTA担当です。 予約がほとんど入らないプランの原因を一緒に考えてください。 【プラン】（例：平日限定・乾杯ドリンク付き） 【状況】（例：2ヶ月で予約2件／検索3ページ目／写真は1枚のみ） 5つの切り口（露出／価格／内容／表現／ニーズとのズレ）で 「怪しさ」を0〜5点で採点し、点数の高いものから 打ち手案を1つずつ挙げてください。 まず状況を確認したいことがあれば、3つまで質問してください。 | E13: ✔ 点数は目安。実際の予約データや検索順位で確かめる ✔ 値下げ・変更の前に、条件と数字を確認する ✔ 個人情報（お客様の名前・電話・メール・予約番号）は入れていない（A様のように置き換える） | F13: ・「なぜこのプランが売れない？」をAIと考える | G13: ・OTAの宿泊プランをAIと考える。まず全体を整理してから ・プラン名を改善する。検索され、選ばれる名前のルール ・プラン説明を改善する。読まれる文の「型」と注意点 | I13: 私は宿のOTA担当です。 予約がほとんど入らないプランの原因を一緒に考えてください。 【プラン】（例：平日限定・乾杯ドリンク付き） 【状況】（例：2ヶ月で予約2件／検索3ページ目／写真は1枚のみ） 5つの切り口（露出／価格／内容／表現／ニーズとのズレ）で 「怪しさ」を0〜5点で採点し、点数の高いものから 打ち手案を1つずつ挙げてください。 まず状況を確認したいことがあれば、3つまで質問してください。
A14: 12 | B14: 売上に困っている | C14: 予約は増えたのに、利益が残らない | D14: =IF(①宿プロフィール!$C$12="はい",①宿プロフィール!$C$14&CHAR(10)&CHAR(10),"")&SUBSTITUTE(SUBSTITUTE(SUBSTITUTE(I14,"{{宿の種類}}",①宿プロフィール!$E$4),"{{立場}}",①宿プロフィール!$E$5),"{{客室数}}",①宿プロフィール!$E$6) -> 私は宿の経営者です。 予約は増えているのに利益が残らない感覚を整理したいです。 【感じていること（そのまま）】 （例：値下げして取る団体が多い／ 人を増やしたがコスト増／休みも取れない） お願い： 1. 「コスト」「単価」「稼働の質」の構造に分類 2. いちばん可能性が高い構造の仮説（1つに絞る） 3. 確かめるべき数字を3つ挙げて 4. 今日から確認できる小さな一歩を1つ | E14: ✔ AIが挙げた仮説を、実際の数字（売上・手数料・人件費など）で確かめる ✔ 価格や人の配置など重要な判断は、人が決める ✔ 個人情報（お客様の名前・電話・メール・予約番号）は入れていない（A様のように置き換える） | F14: ・「忙しいのに儲からない」をAIと整理する | G14: ・売上についてAIと考える。感覚を整理し、打ち手に繋げる ・稼働率についてAIと考える。空いている日を「誰かが来たい日」に変える視点 ・AIと一緒に問題を分解する。「大きな不安」を「対処できる小さな問題」に | I14: 私は宿の経営者です。 予約は増えているのに利益が残らない感覚を整理したいです。 【感じていること（そのまま）】 （例：値下げして取る団体が多い／ 人を増やしたがコスト増／休みも取れない） お願い： 1. 「コスト」「単価」「稼働の質」の構造に分類 2. いちばん可能性が高い構造の仮説（1つに絞る） 3. 確かめるべき数字を3つ挙げて 4. 今日から確認できる小さな一歩を1つ
... A26: 24 | B26: 頭の中を整理したい | C26: 漠然とした不安やモヤモヤが消えない | D26: =IF(①宿プロフィール!$C$12="はい",①宿プロフィール!$C$14&CHAR(10)&CHAR(10),"")&SUBSTITUTE(SUBSTITUTE(SUBSTITUTE(I26,"{{宿の種類}}",①宿プロフィール!$E$4),"{{立場}}",①宿プロフィール!$E$5),"{{客室数}}",①宿プロフィール!$E$6) -> 話に乗ってください。 漠然とした不安が、ずっと頭にあります。 【不安なこと（そのまま書く）】 （将来のこと・後継のこと・お金のこと…なんでも） お願い： 1. まず結論を出さず、聞き返して 2. 話してない部分を1つだけ質問して 3. 今日は「話して整理」が目標です | E26: ✔ 今日は「話して整理する」で十分 ✔ つらさが続く・眠れない日が続くときは、身近な人や専門家、公的な相談窓口へ ✔ 個人情報（お客様の名前・電話・メール・予約番号）は入れていない（A様のように置き換える） | F26: ・「これ、どうしたらいい？」をAIに相談する。まず話して、整理してもらう | G26: ・頭の中のモヤモヤをAIに整理してもらう ・AIと一緒に問題を分解する。「大きな不安」を「対処できる小さな問題」に ・来月やることをAIと整理する。月次の5分レビュー | I26: 話に乗ってください。 漠然とした不安が、ずっと頭にあります。 【不安なこと（そのまま書く）】 （将来のこと・後継のこと・お金のこと…なんでも） お願い： 1. まず結論を出さず、聞き返して 2. 話してない部分を1つだけ質問して 3. 今日は「話して整理」が目標です

Sheet ③記事から探す
A1: 【このシートの使い方】AIと宿サイトの記事の順に、各記事で使う「AIに送る文」をまとめたシートです。記事を読みながら使うとき、またはテーマ（OTA・採用・SNSなど）で探したいときに使います。 上の見出しの▼で、レベルや分類を絞り込めます。使い方は「困りごとから探す」と同じです。（全65件）
A2: 記事No | B2: レベル | C2: 分類 | D2: 読む記事 | E2: 使う場面 | F2: AIに送る文（お願い文） ← ここをコピー | G2: 答えが出たあとに続けて送る一文 | H2: 確認すること
A3: 1 | B3: LEVEL 1｜AIを知る・触る | C3: AIを知る | D3: AIってそもそも何？宿の仕事のことだけ、やさしく説明 | E3: AIに「AI」を説明してもらう（そのままコピーOK） | F3: =IF(①宿プロフィール!$C$12="はい",①宿プロフィール!$C$14&CHAR(10)&CHAR(10),"")&SUBSTITUTE(SUBSTITUTE(SUBSTITUTE(I3,"{{宿の種類}}",①宿プロフィール!$E$4),"{{立場}}",①宿プロフィール!$E$5),"{{客室数}}",①宿プロフィール!$E$6) -> 私は温泉旅館で働いています。パソコンやITはあまり詳しくありません。 「AI」とは何か、中学生にもわかる言葉で説明してください。 一度に全部説明せず、3行ずつ、3回に分けて説明してください。 1回目の説明だけ、まずお願いします。 | H3: ✔ AIの答えは「それらしい」だけのことがある。大事なことは自分で確かめる ✔ 個人情報（お客様の名前・電話・メール・予約番号）は入れていない（A様のように置き換える） | I3: 私は{{宿の種類}}で働いています。パソコンやITはあまり詳しくありません。 「AI」とは何か、中学生にもわかる言葉で説明してください。 一度に全部説明せず、3行ずつ、3回に分けて説明してください。 1回目の説明だけ、まずお願いします。
A4: 2 | B4: LEVEL 1｜AIを知る・触る | C4: AIを知る | D4: ChatGPT・Gemini・Claudeって何が違う？迷ったらどれを使う？ | E4: 3つのAIで比べてみる実験用の文（そのままコピーOK） | F4: =IF(①宿プロフィール!$C$12="はい",①宿プロフィール!$C$14&CHAR(10)&CHAR(10),"")&SUBSTITUTE(SUBSTITUTE(SUBSTITUTE(I4,"{{宿の種類}}",①宿プロフィール!$E$4),"{{立場}}",①宿プロフィール!$E$5),"{{客室数}}",①宿プロフィール!$E$6) -> 私は温泉旅館で働いています。 朝食の写真をSNSに載せたいので、キャプション（説明文）を3案考えてください。 ・雰囲気：素朴であたたかい ・長さ：50字以内 ・ハッシュタグは2個まで | H4: ✔ AIの答えは「それらしい」だけのことがある。大事なことは自分で確かめる ✔ 個人情報（お客様の名前・電話・メール・予約番号）は入れていない（A様のように置き換える） | I4: 私は{{宿の種類}}で働いています。 朝食の写真をSNSに載せたいので、キャプション（説明文）を3案考えてください。 ・雰囲気：素朴であたたかい ・長さ：50字以内 ・ハッシュタグは2個まで
A5: 3 | B5: LEVEL 1｜AIを知る・触る | C5: AIを知る | D5: AIにできること・できないこと。まず知っておきたい境界線 | E5: AI本人に苦手なことを聞く（そのままコピーOK） | F5: =IF(①宿プロフィール!$C$12="はい",①宿プロフィール!$C$14&CHAR(10)&CHAR(10),"")&SUBSTITUTE(SUBSTITUTE(SUBSTITUTE(I5,"{{宿の種類}}",①宿プロフィール!$E$4),"{{立場}}",①宿プロフィール!$E$5),"{{客室数}}",①宿プロフィール!$E$6) -> 私は温泉旅館で働いています。AIを仕事で使い始めたところです。 あなた（AI）が「これは苦手」「間違えることがある」と思うことを、 宿の仕事に関係する例を3つ挙げて、やさしく説明してください。 あわせて、代わりに人がやるべきことも教えてください。 | G5: 逆に、あなた（AI）が宿の仕事で一番得意なのは何ですか？ 今日から試せるものを3つ、具体的に教えてください。 | H5: ✔ AIの答えは「それらしい」だけのことがある。大事なことは自分で確かめる ✔ 個人情報（お客様の名前・電話・メール・予約番号）は入れていない（A様のように置き換える） | I5: 私は{{宿の種類}}で働いています。AIを仕事で使い始めたところです。 あなた（AI）が「これは苦手」「間違えることがある」と思うことを、 宿の仕事に関係する例を3つ挙げて、やさしく説明してください。 あわせて、代わりに人がやるべきことも教えてください。
A6: 4 | B6: LEVEL 1｜AIを知る・触る | C6: AIを知る | D6: AIを宿の仕事に使うと、何が変わる？5つの場面でイメージ | E6: 「この部分だけ手伝って」と頼む文（○○を自分用に書き換え） | F6: =IF(①宿プロフィール!$C$12="はい",①宿プロフィール!$C$14&CHAR(10)&CHAR(10),"")&SUBSTITUTE(SUBSTITUTE(SUBSTITUTE(I6,"{{宿の種類}}",①宿プロフィール!$E$4),"{{立場}}",①宿プロフィール!$E$5),"{{客室数}}",①宿プロフィール!$E$6) -> 私は温泉旅館で働いています。 「○○」という作業の中で、いちばん面倒なのは「△△」の部分です。 この作業をAIに手伝ってもらうとしたら、 どんな頼み方がありますか？ 今日から試せるものを3つ、具体的な例文つきで教えてください。 | G6: このやり方を毎日続けたら、月にどれくらい時間が浮きそうですか？ ざっくりでいいので、計算の考え方と一緒に教えてください。 | H6: ✔ AIの答えは「それらしい」だけのことがある。大事なことは自分で確かめる ✔ 個人情報（お客様の名前・電話・メール・予約番号）は入れていない（A様のように置き換える） | I6: 私は{{宿の種類}}で働いています。 「○○」という作業の中で、いちばん面倒なのは「△△」の部分です。 この作業をAIに手伝ってもらうとしたら、 どんな頼み方がありますか？ 今日から試せるものを3つ、具体的な例文つきで教えてください。
A7: 5 | B7: LEVEL 1｜AIを知る・触る | C7: AIを始める | D7: ChatGPTを始めてみよう。登録からはじめての質問まで | E7: ChatGPTへの、はじめてのあいさつ（そのままコピーOK） | F7: =IF(①宿プロフィール!$C$12="はい",①宿プロフィール!$C$14&CHAR(10)&CHAR(10),"")&SUBSTITUTE(SUBSTITUTE(SUBSTITUTE(I7,"{{宿の種類}}",①宿プロフィール!$E$4),"{{立場}}",①宿プロフィール!$E$5),"{{客室数}}",①宿プロフィール!$E$6) -> はじめまして。私は温泉旅館で働いています。 AIを使うのは今日が初めてです。 まず、あなた（AI）にできることを、3つだけ教えてください。 説明は1行ずつ、宿の仕事の例つきでお願いします。 | H7: ✔ アカウントは個人ごとに作り、パスワードは共有しない ✔ 画面や料金は変わる。最新の案内を確認する ✔ 個人情報（お客様の名前・電話・メール・予約番号）は入れていない（A様のように置き換える） | I7: はじめまして。私は{{宿の種類}}で働いています。 AIを使うのは今日が初めてです。 まず、あなた（AI）にできることを、3つだけ教えてください。 説明は1行ずつ、宿の仕事の例つきでお願いします。
A8: 6 | B8: LEVEL 1｜AIを知る・触る | C8: AIを始める | D8: Geminiを始めてみよう。Googleアカウントがあればすぐ使える | E8: Geminiへの、はじめてのあいさつ（そのままコピーOK） | F8: =IF(①宿プロフィール!$C$12="はい",①宿プロフィール!$C$14&CHAR(10)&CHAR(10),"")&SUBSTITUTE(SUBSTITUTE(SUBSTITUTE(I8,"{{宿の種類}}",①宿プロフィール!$E$4),"{{立場}}",①宿プロフィール!$E$5),"{{客室数}}",①宿プロフィール!$E$6) -> はじめまして。私は温泉旅館で働いています。 AIを使うのは今日が初めてです。 私の仕事（予約対応・お客様対応・文章書き）の中で、 あなたに手伝ってもらえることを3つ、今日から試せる形で教えてください。 | H8: ✔ アカウントは個人ごとに作り、パスワードは共有しない ✔ 画面や料金は変わる。最新の案内を確認する ✔ 個人情報（お客様の名前・電話・メール・予約番号）は入れていない（A様のように置き換える） | I8: はじめまして。私は{{宿の種類}}で働いています。 AIを使うのは今日が初めてです。 私の仕事（予約対応・お客様対応・文章書き）の中で、 あなたに手伝ってもらえることを3つ、今日から試せる形で教えてください。
A9: 7 | B9: LEVEL 1｜AIを知る・触る | C9: AIを始める | D9: Claudeを始めてみよう。丁寧な日本語に定評のあるAI | E9: Claudeへの、はじめてのあいさつ（そのままコピーOK） | F9: =IF(①宿プロフィール!$C$12="はい",①宿プロフィール!$C$14&CHAR(10)&CHAR(10),"")&SUBSTITUTE(SUBSTITUTE(SUBSTITUTE(I9,"{{宿の種類}}",①宿プロフィール!$E$4),"{{立場}}",①宿プロフィール!$E$5),"{{客室数}}",①宿プロフィール!$E$6) -> はじめまして。私は温泉旅館の女将です。 AIを使うのは初めてで、丁寧な文章作りを手伝ってほしいと思っています。 まず、宿の仕事であなたに頼めることを、 例を交えて3つ教えてください。 | H9: ✔ アカウントは個人ごとに作り、パスワードは共有しない ✔ 画面や料金は変わる。最新の案内を確認する ✔ 個人情報（お客様の名前・電話・メール・予約番号）は入れていない（A様のように置き換える） | I9: はじめまして。私は{{宿の種類}}の{{立場}}です。 AIを使うのは初めてで、丁寧な文章作りを手伝ってほしいと思っています。 まず、宿の仕事であなたに頼めることを、 例を交えて3つ教えてください。
A10: 8 | B10: LEVEL 1｜AIを知る・触る | C10: AIを始める | D10: AIを使うときに知っておきたいこと【個人情報・確認の基本】 | E10: 宿のAI利用ルール（3カ条）を作ってもらう（そのままコピーOK） | F10: =IF(①宿プロフィール!$C$12="はい",①宿プロフィール!$C$14&CHAR(10)&CHAR(10),"")&SUBSTITUTE(SUBSTITUTE(SUBSTITUTE(I10,"{{宿の種類}}",①宿プロフィール!$E$4),"{{立場}}",①宿プロフィール!$E$5),"{{客室数}}",①宿プロフィール!$E$6) -> 私は客室12室の温泉旅館を経営しています。 スタッフがAI（ChatGPTなど）を仕事で安全に使えるように、 わかりやすい「館内ルール案」を作ってください。 ・項目は3つまで ・各項目は「やっていいこと／だめなこと」の形で ・ITが苦手なスタッフでも読める言葉で まず私に、宿の状況を確認したいことがあれば質問してください。 質問は一度に3つまででお願いします。 | G10: 次の文章を、AIに入力できる安全な形に直してください。 お客様の名前・連絡先・宿の固有名詞は伏せてください。 （ここに、あなたの文章の一部を貼り付け） | H10: ✔ お客様の名前・連絡先・予約番号などは入れない ✔ 会話の保存の設定は変わることがある。施設のルールと設定を確認する ✔ 個人情報（お客様の名前・電話・メール・予約番号）は入れていない（A様のように置き換える） | I10: 私は客室{{客室数}}室の{{宿の種類}}を経営しています。 スタッフがAI（ChatGPTなど）を仕事で安全に使えるように、 わかりやすい「館内ルール案」を作ってください。 ・項目は3つまで ・各項目は「やっていいこと／だめなこと」の形で ・ITが苦手なスタッフでも読める言葉で まず私に、宿の状況を確認したいことがあれば質問してください。 質問は一度に3つまででお願いします。
A11: 9 | B11: LEVEL 1｜AIを知る・触る | C11: AIに話しかける | D11: AIには何を聞けばいい？宿の仕事で使える質問カタログ | E11: 「何を聞けばいいか」をAIに聞いてしまう（そのままコピーOK） | F11: =IF(①宿プロフィール!$C$12="はい",①宿プロフィール!$C$14&CHAR(10)&CHAR(10),"")&SUBSTITUTE(SUBSTITUTE(SUBSTITUTE(I11,"{{宿の種類}}",①宿プロフィール!$E$4),"{{立場}}",①宿プロフィール!$E$5),"{{客室数}}",①宿プロフィール!$E$6) -> 私は温泉旅館で働いています。AIを使い始めたばかりです。 正直、あなたに「何を聞けばいいか」がわかりません。 宿の仕事でAIに聞けることを、 「教えて」「作って」「一緒に考えて」の3つに分けて、 それぞれ実際に使える質問文を3つずつ、今日試せる形で教えてください。 | H11: ✔ 答えが足りない・ずれているときは、条件を足してもう一度頼む ✔ 数字や事実は自分で確認する ✔ 個人情報（お客様の名前・電話・メール・予約番号）は入れていない（A様のように置き換える） | I11: 私は{{宿の種類}}で働いています。AIを使い始めたばかりです。 正直、あなたに「何を聞けばいいか」がわかりません。 宿の仕事でAIに聞けることを、 「教えて」「作って」「一緒に考えて」の3つに分けて、 それぞれ実際に使える質問文を3つずつ、今日試せる形で教えてください。
A12: 10 | B12: LEVEL 1｜AIを知る・触る | C12: AIに話しかける | D12: AIに自分の宿を説明してみよう。背景を伝えると答えが変わる | E12: 私の宿プロフィール（穴埋めして使う） | F12: =IF(①宿プロフィール!$C$12="はい",①宿プロフィール!$C$14&CHAR(10)&CHAR(10),"")&SUBSTITUTE(SUBSTITUTE(SUBSTITUTE(I12,"{{宿の種類}}",①宿プロフィール!$E$4),"{{立場}}",①宿プロフィール!$E$5),"{{客室数}}",①宿プロフィール!$E$6) -> 私の宿について、以下の前提で相談に乗ってください。 ・宿の種別：（例：温泉旅館） ・客室数：（例：12室） ・エリア：（例：山あいの温泉地） ・客単価：（例：1泊2食で2万円前後） ・主な客層：（例：50〜70代の夫婦が中心） ・スタッフ：（例：家族4名＋パート3名） ・いまの課題：（例：平日の稼働が低い） この内容を前提として覚えておき、 今後の質問にはできるだけこの状況に合わせて答えてください。 まず、内容の確認だけお願いします。 | G12: 前提を踏まえて、「いまの課題」の改善に向けて、 まず確認すべきことを3つ挙げてください。 大掛かりな提案ではなく、今週確認できることでお願いします。 | H12: ✔ 会話の記憶・保存の設定は、サービスや時期で違う。個人情報はプロフィールに入れない ✔ 個人情報（お客様の名前・電話・メール・予約番号）は入れていない（A様のように置き換える） | I12: 私の宿について、以下の前提で相談に乗ってください。 ・宿の種別：（例：温泉旅館） ・客室数：（例：12室） ・エリア：（例：山あいの温泉地） ・客単価：（例：1泊2食で2万円前後） ・主な客層：（例：50〜70代の夫婦が中心） ・スタッフ：（例：家族4名＋パート3名） ・いまの課題：（例：平日の稼働が低い） この内容を前提として覚えておき、 今後の質問にはできるだけこの状況に合わせて答えてください。 まず、内容の確認だけお願いします。
A13: 11 | B13: LEVEL 1｜AIを知る・触る | C13: AIに話しかける | D13: AIに質問してみよう。送る→読む→深掘りの練習 | E13: はじめての質問（そのままコピーOK） | F13: =IF(①宿プロフィール!$C$12="はい",①宿プロフィール!$C$14&CHAR(10)&CHAR(10),"")&SUBSTITUTE(SUBSTITUTE(SUBSTITUTE(I13,"{{宿の種類}}",①宿プロフィール!$E$4),"{{立場}}",①宿プロフィール!$E$5),"{{客室数}}",①宿プロフィール!$E$6) -> 私は温泉旅館で働いています。 朝食の会場で、お客様にかけると喜ばれる一言を3つ考えてください。 ・相手：50〜70代の夫婦 ・雰囲気：堅すぎず、あたたかい ・長さ：それぞれ20字以内 | H13: ✔ 答えが足りない・ずれているときは、条件を足してもう一度頼む ✔ 数字や事実は自分で確認する ✔ 個人情報（お客様の名前・電話・メール・予約番号）は入れていない（A様のように置き換える） | I13: 私は{{宿の種類}}で働いています。 朝食の会場で、お客様にかけると喜ばれる一言を3つ考えてください。 ・相手：50〜70代の夫婦 ・雰囲気：堅すぎず、あたたかい ・長さ：それぞれ20字以内
A14: 12 | B14: LEVEL 1｜AIを知る・触る | C14: AIに話しかける | D14: AIの答えが「なんか違う」ときはどうする？聞き直しの3つの型 | E14: 一般論すぎるとき（背景を足す） | F14: =IF(①宿プロフィール!$C$12="はい",①宿プロフィール!$C$14&CHAR(10)&CHAR(10),"")&SUBSTITUTE(SUBSTITUTE(SUBSTITUTE(I14,"{{宿の種類}}",①宿プロフィール!$E$4),"{{立場}}",①宿プロフィール!$E$5),"{{客室数}}",①宿プロフィール!$E$6) -> ありがとうございます。もう少し「うちの宿」寄りにお願いします。 補足情報です： ・客室数：（例：12室） ・客層：（例：50〜70代の夫婦が中心） ・いまの課題：（例：平日の稼働が低い） この前提で、さきほどの回答を具体化してください。 | H14: ✔ 答えが足りない・ずれているときは、条件を足してもう一度頼む ✔ 数字や事実は自分で確認する ✔ 個人情報（お客様の名前・電話・メール・予約番号）は入れていない（A様のように置き換える） | I14: ありがとうございます。もう少し「うちの宿」寄りにお願いします。 補足情報です： ・客室数：（例：12室） ・客層：（例：50〜70代の夫婦が中心） ・いまの課題：（例：平日の稼働が低い） この前提で、さきほどの回答を具体化してください。
A15: 12 | B15: LEVEL 1｜AIを知る・触る | C15: AIに話しかける | D15: AIの答えが「なんか違う」ときはどうする？聞き直しの3つの型 | E15: 聞いたことと違うとき（範囲を絞る） | F15: =IF(①宿プロフィール!$C$12="はい",①宿プロフィール!$C$14&CHAR(10)&CHAR(10),"")&SUBSTITUTE(SUBSTITUTE(SUBSTITUTE(I15,"{{宿の種類}}",①宿プロフィール!$E$4),"{{立場}}",①宿プロフィール!$E$5),"{{客室数}}",①宿プロフィール!$E$6) -> すみません、私が聞きたいのは「◯◯」の部分だけです。 他の話はいったん置いて、◯◯についてだけ、 箇条書き3点で答え直してください。 | H15: ✔ 答えが足りない・ずれているときは、条件を足してもう一度頼む ✔ 数字や事実は自分で確認する ✔ 個人情報（お客様の名前・電話・メール・予約番号）は入れていない（A様のように置き換える） | I15: すみません、私が聞きたいのは「◯◯」の部分だけです。 他の話はいったん置いて、◯◯についてだけ、 箇条書き3点で答え直してください。
A16: 12 | B16: LEVEL 1｜AIを知る・触る | C16: AIに話しかける | D16: AIの答えが「なんか違う」ときはどうする？聞き直しの3つの型 | E16: 事実が怪しいとき（出どころを聞く） | F16: =IF(①宿プロフィール!$C$12="はい",①宿プロフィール!$C$14&CHAR(10)&CHAR(10),"")&SUBSTITUTE(SUBSTITUTE(SUBSTITUTE(I16,"{{宿の種類}}",①宿プロフィール!$E$4),"{{立場}}",①宿プロフィール!$E$5),"{{客室数}}",①宿プロフィール!$E$6) -> さきほどの回答の中で、数字や固有名詞が含まれている部分は どこですか？ その情報はどの程度確かですか？ あいまいな部分は、あいまいだと正直に教えてください。 | H16: ✔ 答えが足りない・ずれているときは、条件を足してもう一度頼む ✔ 数字や事実は自分で確認する ✔ 個人情報（お客様の名前・電話・メール・予約番号）は入れていない（A様のように置き換える） | I16: さきほどの回答の中で、数字や固有名詞が含まれている部分は どこですか？ その情報はどの程度確かですか？ あいまいな部分は、あいまいだと正直に教えてください。
A17: 13 | B17: LEVEL 1｜AIを知る・触る | C17: AIに話しかける | D17: 「もう少し詳しく」とAIに聞こう。会話を深める5つのフレーズ | E17: 深掘りフレーズ集（好きなものをそのまま送る） | F17: =IF(①宿プロフィール!$C$12="はい",①宿プロフィール!$C$14&CHAR(10)&CHAR(10),"")&SUBSTITUTE(SUBSTITUTE(SUBSTITUTE(I17,"{{宿の種類}}",①宿プロフィール!$E$4),"{{立場}}",①宿プロフィール!$E$5),"{{客室数}}",①宿プロフィール!$E$6) -> もう少し具体的に教えてください。 うちの宿（客室12室・客単価◯円前後）の場合に置き換えてください。 例を3つ挙げてください。 要点を表にまとめてください。 良さそうな順に並べて、理由も添えてください。 あえて反対の立場から、懸念点を挙げてください。 | H17: ✔ 答えが足りない・ずれているときは、条件を足してもう一度頼む ✔ 数字や事実は自分で確認する ✔ 個人情報（お客様の名前・電話・メール・予約番号）は入れていない（A様のように置き換える） | I17: もう少し具体的に教えてください。 うちの宿（客室{{客室数}}室・客単価◯円前後）の場合に置き換えてください。 例を3つ挙げてください。 要点を表にまとめてください。 良さそうな順に並べて、理由も添えてください。 あえて反対の立場から、懸念点を挙げてください。
A18: 14 | B18: LEVEL 1｜AIを知る・触る | C18: まず仕事で使ってみる | D18: AIにメールを書いてもらう。まずは「お礼メール」から | E18: お礼メールの下書きを頼む（条件を書き換えて送る） | F18: =IF(①宿プロフィール!$C$12="はい",①宿プロフィール!$C$14&CHAR(10)&CHAR(10),"")&SUBSTITUTE(SUBSTITUTE(SUBSTITUTE(I18,"{{宿の種類}}",①宿プロフィール!$E$4),"{{立場}}",①宿プロフィール!$E$5),"{{客室数}}",①宿プロフィール!$E$6) -> あなたは温泉旅館の女将です。 本日チェックアウトされたA様へ送る、お礼メールの文面を作ってください。 ・目的：宿泊のお礼と、また季節を変えて訪れてほしい気持ちを伝える ・長さ：200字程度 ・口調：丁寧であたたかい。堅苦しすぎない ・構成：挨拶→感謝→ひとこと→締め 文面のみをお願いします。 | G18: ありがとうございます。 文中の「季節のひとこと」の部分を、春夏秋冬それぞれ別パターンで 2案ずつ考えてください。あたたかみのある表現でお願いします。 | H18: ✔ 宛名・日付・金額・時間が合っている ✔ 送る前に最後まで自分で読んだ ✔ 個人情報（お客様の名前・電話・メール・予約番号）は入れていない（A様のように置き換える） | I18: あなたは{{宿の種類}}の{{立場}}です。 本日チェックアウトされたA様へ送る、お礼メールの文面を作ってください。 ・目的：宿泊のお礼と、また季節を変えて訪れてほしい気持ちを伝える ・長さ：200字程度 ・口調：丁寧であたたかい。堅苦しすぎない ・構成：挨拶→感謝→ひとこと→締め 文面のみをお願いします。
A19: 15 | B19: LEVEL 1｜AIを知る・触る | C19: まず仕事で使ってみる | D19: AIに口コミ返信を考えてもらう。感謝と誠意を、早く・気持ちよく | E19: 良い口コミへの返信下書きを頼む（そのままコピーOK） | F19: =IF(①宿プロフィール!$C$12="はい",①宿プロフィール!$C$14&CHAR(10)&CHAR(10),"")&SUBSTITUTE(SUBSTITUTE(SUBSTITUTE(I19,"{{宿の種類}}",①宿プロフィール!$E$4),"{{立場}}",①宿プロフィール!$E$5),"{{客室数}}",①宿プロフィール!$E$6) -> 私は温泉旅館の女将です。宿泊サイトの口コミへの返信文を作ってください。 口コミの要点： ・夕食の地元食材がおいしかった ・スタッフの対応が丁寧だった ・また来たいと書いてくれている 条件： ・長さ：150字前後 ・口調：感謝の気持ちが伝わる、あたたかく ・「またのお越しを」の言い換え表現を使う ・定型文っぽくしない 文面のみお願いします。 | G19: この返信文を「フォーマル寄り」「あたたか寄り」「簡潔寄り」の 3トーンで書き分けてください。違いがわかるようにお願いします。 | H19: ✔ お客様が特定できる情報（部屋・日付・人数・同伴者）を書いていない ✔ 返信は公開される。厳しい口コミは、急がず責任者にも見てもらう ✔ 個人情報（お客様の名前・電話・メール・予約番号）は入れていない（A様のように置き換える） | I19: 私は{{宿の種類}}の{{立場}}です。宿泊サイトの口コミへの返信文を作ってください。 口コミの要点： ・夕食の地元食材がおいしかった ・スタッフの対応が丁寧だった ・また来たいと書いてくれている 条件： ・長さ：150字前後 ・口調：感謝の気持ちが伝わる、あたたかく ・「またのお越しを」の言い換え表現を使う ・定型文っぽくしない 文面のみお願いします。
A20: 15 | B20: LEVEL 1｜AIを知る・触る | C20: まず仕事で使ってみる | D20: AIに口コミ返信を考えてもらう。感謝と誠意を、早く・気持ちよく | E20: 厳しい口コミへの返信下書きを頼む（要点を書き換えて送る） | F20: =IF(①宿プロフィール!$C$12="はい",①宿プロフィール!$C$14&CHAR(10)&CHAR(10),"")&SUBSTITUTE(SUBSTITUTE(SUBSTITUTE(I20,"{{宿の種類}}",①宿プロフィール!$E$4),"{{立場}}",①宿プロフィール!$E$5),"{{客室数}}",①宿プロフィール!$E$6) -> 私は温泉旅館の女将です。厳しい内容の口コミへの返信文を作ってください。 口コミの要点（個人情報は除いています）： ・◯◯（例：部屋の設備の古さ）への指摘 ・◯◯（例：期待との差）への残念という気持ち 条件： ・長さ：200字前後 ・口調：誠実に。言い訳がましくしない ・構成：お礼→受け止め→改善への姿勢→締め ・反論はしない（ただし事実確認はこちらで済ませます） 文面のみお願いします。 | H20: ✔ お客様が特定できる情報（部屋・日付・人数・同伴者）を書いていない ✔ 返信は公開される。厳しい口コミは、急がず責任者にも見てもらう ✔ 個人情報（お客様の名前・電話・メール・予約番号）は入れていない（A様のように置き換える） | I20: 私は{{宿の種類}}の{{立場}}です。厳しい内容の口コミへの返信文を作ってください。 口コミの要点（個人情報は除いています）： ・◯◯（例：部屋の設備の古さ）への指摘 ・◯◯（例：期待との差）への残念という気持ち 条件： ・長さ：200字前後 ・口調：誠実に。言い訳がましくしない ・構成：お礼→受け止め→改善への姿勢→締め ・反論はしない（ただし事実確認はこちらで済ませます） 文面のみお願いします。
A21: 16 | B21: LEVEL 1｜AIを知る・触る | C21: まず仕事で使ってみる | D21: AIに館内案内を作ってもらう。やさしく伝わる文章の作り方 | E21: 館内案内をやさしい文章にしてもらう（箇条書きを差し替えて送る） | F21: =IF(①宿プロフィール!$C$12="はい",①宿プロフィール!$C$14&CHAR(10)&CHAR(10),"")&SUBSTITUTE(SUBSTITUTE(SUBSTITUTE(I21,"{{宿の種類}}",①宿プロフィール!$E$4),"{{立場}}",①宿プロフィール!$E$5),"{{客室数}}",①宿プロフィール!$E$6) -> 私は温泉旅館のフロント担当です。 館内掲示用の案内文を作ってください。 載せたい情報： ・（例：大浴場の営業は15時〜23時、翌朝は6時〜9時） ・（例：タオルとバスタオルは客室のものを持参） ・（例：シャンプー類は浴場に設置あり） ・（例：刺青・タトゥーの方は入浴をご遠慮いただくルールになっている） 条件： ・読み手：宿泊したばかりのお客様 ・口調：ていねいでやわらかい（「〜なっております」調は避ける） ・長さ：150字程度＋注意事項は箇条書き ・大事なこと（時間）が最初に目に入る構成 文面のみお願いします。 | H21: ✔ 掲示する前に、実際の設備・時間・ルールと合っているか確認する ✔ 個人情報（お客様の名前・電話・メール・予約番号）は入れていない（A様のように置き換える） | I21: 私は{{宿の種類}}のフロント担当です。 館内掲示用の案内文を作ってください。 載せたい情報： ・（例：大浴場の営業は15時〜23時、翌朝は6時〜9時） ・（例：タオルとバスタオルは客室のものを持参） ・（例：シャンプー類は浴場に設置あり） ・（例：刺青・タトゥーの方は入浴をご遠慮いただくルールになっている） 条件： ・読み手：宿泊したばかりのお客様 ・口調：ていねいでやわらかい（「〜なっております」調は避ける） ・長さ：150字程度＋注意事項は箇条書き ・大事なこと（時間）が最初に目に入る構成 文面のみお願いします。
A22: 17 | B22: LEVEL 1｜AIを知る・触る | C22: まず仕事で使ってみる | D22: AIに宿泊プランの文章を作ってもらう。“売れる予感”のある文の骨格 | E22: プラン名＋説明文の下書きを頼む（括弧を埋めて送る） | F22: =IF(①宿プロフィール!$C$12="はい",①宿プロフィール!$C$14&CHAR(10)&CHAR(10),"")&SUBSTITUTE(SUBSTITUTE(SUBSTITUTE(I22,"{{宿の種類}}",①宿プロフィール!$E$4),"{{立場}}",①宿プロフィール!$E$5),"{{客室数}}",①宿プロフィール!$E$6) -> あなたは宿の企画担当です。 宿泊プランの「プラン名3案」と「説明文（200字程度）」を作ってください。 ・ターゲット：（例：結婚記念日の50〜60代の夫婦） ・体験の核：（例：夕食時に係が記念写真を撮り、翌朝写真をプレゼント） ・宿の雰囲気：（例：静かな山あいの小さな温泉宿） ・特典・条件：（例：スパークリングワイン1杯付き。2名1室限定） ・説明文の構成：誰に→何がうれしいか→特典→締めのひと言 ・プラン名：20字以内。検索されそうな言葉を含める 説明文は最も良いと思う1案のみ添えてください。 | G22: 説明文はこのままでOKです。 プラン名だけ、あと10案ください。 うち3案は少しユーモアのあるもの、3案は高級感のあるもので。 それぞれ、どんな狙いの名前か一言添えてください。 | H22: ✔ 料金・条件が、OTA管理画面の実際の内容と合っている ✔ 「最安値」「日本一」など根拠のない言い切りが入っていない ✔ 個人情報（お客様の名前・電話・メール・予約番号）は入れていない（A様のように置き換える） | I22: あなたは宿の企画担当です。 宿泊プランの「プラン名3案」と「説明文（200字程度）」を作ってください。 ・ターゲット：（例：結婚記念日の50〜60代の夫婦） ・体験の核：（例：夕食時に係が記念写真を撮り、翌朝写真をプレゼント） ・宿の雰囲気：（例：静かな山あいの小さな温泉宿） ・特典・条件：（例：スパークリングワイン1杯付き。2名1室限定） ・説明文の構成：誰に→何がうれしいか→特典→締めのひと言 ・プラン名：20字以内。検索されそうな言葉を含める 説明文は最も良いと思う1案のみ添えてください。
A23: 18 | B23: LEVEL 1｜AIを知る・触る | C23: 自分の宿向けに変えてみる | D23: コピペしたAIへのお願いを、自分の宿向けに変えてみよう【STEP 2】 | E23: 比較練習の土台になる文（2種類作って送る） | F23: =IF(①宿プロフィール!$C$12="はい",①宿プロフィール!$C$14&CHAR(10)&CHAR(10),"")&SUBSTITUTE(SUBSTITUTE(SUBSTITUTE(I23,"{{宿の種類}}",①宿プロフィール!$E$4),"{{立場}}",①宿プロフィール!$E$5),"{{客室数}}",①宿プロフィール!$E$6) -> 【A：そのまま版】 あなたは宿の企画担当です。平日の集客アイデアを3つください。 【B：背景つき版】 あなたは宿の企画担当です。 私の宿は「山あいの温泉地にある客室12室の宿」で、 客層は50〜70代の夫婦が中心、課題は平日の稼働率の低さです。 この条件に合う平日の集客アイデアを3つください。 | G23: さきほどのアイデアについて、条件だけ変えます。 ・個数：3つ→7つ ・難易度：今週できる小さなことだけ 上記で出し直してください。 | H23: ✔ 保存した文に、個人情報や秘密が入っていない ✔ 個人情報（お客様の名前・電話・メール・予約番号）は入れていない（A様のように置き換える） | I23: 【A：そのまま版】 あなたは宿の企画担当です。平日の集客アイデアを3つください。 【B：背景つき版】 あなたは宿の企画担当です。 私の宿は「山あいの温泉地にある客室12室の宿」で、 客層は50〜70代の夫婦が中心、課題は平日の稼働率の低さです。 この条件に合う平日の集客アイデアを3つください。
A24: 19 | B24: LEVEL 1｜AIを知る・触る | C24: 自分の宿向けに変えてみる | D24: AIへの質問を、一部分だけ変更してみよう【STEP 3】 | E24: 条件ブロックの練習用（差し替えて比較） | F24: =IF(①宿プロフィール!$C$12="はい",①宿プロフィール!$C$14&CHAR(10)&CHAR(10),"")&SUBSTITUTE(SUBSTITUTE(SUBSTITUTE(I24,"{{宿の種類}}",①宿プロフィール!$E$4),"{{立場}}",①宿プロフィール!$E$5),"{{客室数}}",①宿プロフィール!$E$6) -> 私は温泉旅館で働いています。 「チェックイン時のお出迎えの言葉」を3つ考えてください。 【条件ブロック・例A】 ・長さ：それぞれ15字以内 ・口調：格式高く、静かな旅館らしく ・形式：箇条書き 【条件ブロック・例B】 ・長さ：それぞれ25字以内 ・口調：あたたかく、家庭に迎えるような ・形式：表（言葉／ねらい） | G24: この質問文に追加できる「条件」の候補を挙げてください。 口調・長さ・形式以外のものも含めて、5つ。 それぞれ「入れると答えがどう変わるか」も添えてください。 | H24: ✔ 保存した文に、個人情報や秘密が入っていない ✔ 個人情報（お客様の名前・電話・メール・予約番号）は入れていない（A様のように置き換える） | I24: 私は{{宿の種類}}で働いています。 「チェックイン時のお出迎えの言葉」を3つ考えてください。 【条件ブロック・例A】 ・長さ：それぞれ15字以内 ・口調：格式高く、静かな旅館らしく ・形式：箇条書き 【条件ブロック・例B】 ・長さ：それぞれ25字以内 ・口調：あたたかく、家庭に迎えるような ・形式：表（言葉／ねらい）
A25: 20 | B25: LEVEL 1｜AIを知る・触る | C25: 自分の宿向けに変えてみる | D25: 自分の希望をAIに追加してみよう【STEP 4】。お願い文の育て方 | E25: 希望を1行足す例（SNS投稿の依頼文） | F25: =IF(①宿プロフィール!$C$12="はい",①宿プロフィール!$C$14&CHAR(10)&CHAR(10),"")&SUBSTITUTE(SUBSTITUTE(SUBSTITUTE(I25,"{{宿の種類}}",①宿プロフィール!$E$4),"{{立場}}",①宿プロフィール!$E$5),"{{客室数}}",①宿プロフィール!$E$6) -> 私は温泉旅館で働いています。 夕食の写真に添えるSNS投稿文を3案考えてください。 ・雰囲気：素朴であたたかい ・長さ：80字以内 ・こだわり：「絶景」「最高」などの大げさな言葉は使わず、 静かな宿らしい言い回しにすること ・避けたいこと：絵文字の多用（1文につき1個まで） | G25: 上の条件（80字以内／こだわり／避けたいこと）について、 両立しにくい部分があれば指摘してください。 あわせて、優先順位の付け方も提案してください。 | H25: ✔ 保存した文に、個人情報や秘密が入っていない ✔ 個人情報（お客様の名前・電話・メール・予約番号）は入れていない（A様のように置き換える） | I25: 私は{{宿の種類}}で働いています。 夕食の写真に添えるSNS投稿文を3案考えてください。 ・雰囲気：素朴であたたかい ・長さ：80字以内 ・こだわり：「絶景」「最高」などの大げさな言葉は使わず、 静かな宿らしい言い回しにすること ・避けたいこと：絵文字の多用（1文につき1個まで）
A26: 21 | B26: LEVEL 2｜AIを宿の仕事で使う | C26: 接客・フロント | D26: お客様へのメールをAIに手伝ってもらう【実務編】 | E26: 状況別メールの型を作ってもらう（そのままコピーOK） | F26: =IF(①宿プロフィール!$C$12="はい",①宿プロフィール!$C$14&CHAR(10)&CHAR(10),"")&SUBSTITUTE(SUBSTITUTE(SUBSTITUTE(I26,"{{宿の種類}}",①宿プロフィール!$E$4),"{{立場}}",①宿プロフィール!$E$5),"{{客室数}}",①宿プロフィール!$E$6) -> 私は温泉旅館のフロント担当です。 お客様に送る定型メールの「型」を2種類作ってください。 【1】予約確認メール（予約完了をお知らせする） 【2】前日のご連絡メール（到着予定時刻と夕食時間の確認） 共通の条件： ・長さ：250字前後 ・口調：丁寧・あたたか・簡潔 ・構成：挨拶→用件→確認してほしいこと→締め ・途中に「【宿の所感：ここに宿の言葉を入れる】」という 差し込み場所を1行入れる ・お客様の名前は「A様」で | G26: キャンセルのご連絡をいただいたお客様への一次返信文を作ってください。 ・残念の気持ちは伝えるが、引き留めない ・またの機会をさりげなく歓迎する ・キャンセル料の話はここでは書かない ・200字以内 | H26: ✔ 宛名・日付・金額・時間が合っている ✔ デリケートな内容は、責任者が確認してから送る ✔ 個人情報（お客様の名前・電話・メール・予約番号）は入れていない（A様のように置き換える） | I26: 私は{{宿の種類}}のフロント担当です。 お客様に送る定型メールの「型」を2種類作ってください。 【1】予約確認メール（予約完了をお知らせする） 【2】前日のご連絡メール（到着予定時刻と夕食時間の確認） 共通の条件： ・長さ：250字前後 ・口調：丁寧・あたたか・簡潔 ・構成：挨拶→用件→確認してほしいこと→締め ・途中に「【宿の所感：ここに宿の言葉を入れる】」という 差し込み場所を1行入れる ・お客様の名前は「A様」で
A27: 22 | B27: LEVEL 2｜AIを宿の仕事で使う | C27: 接客・フロント | D27: 電話・問い合わせ対応を整理する。「何と答える？」の蓄積をAIと | E27: 電話対応の回答表を作ってもらう（質問例を差し替えて送る） | F27: =IF(①宿プロフィール!$C$12="はい",①宿プロフィール!$C$14&CHAR(10)&CHAR(10),"")&SUBSTITUTE(SUBSTITUTE(SUBSTITUTE(I27,"{{宿の種類}}",①宿プロフィール!$E$4),"{{立場}}",①宿プロフィール!$E$5),"{{客室数}}",①宿プロフィール!$E$6) -> 私は温泉旅館のフロント担当です。 電話でよく受ける質問への「対応メモ」を表にしてください。 よくある質問： 1. （例：ペットは一緒に泊まれますか） 2. （例：送迎はありますか、時間は） 3. （例：チェックインの最終は何時ですか） 4. （例：アレルギー対応はできますか） 5. （例：キャンセル料はいつから） 表の列：質問／まず答える一文／確認すべきこと／即答or保留 回答文は、お客様への言葉を想定した丁寧な表現で。 | G27: 「できかねます」のお断り文句を、 宿のお客様向けにやわらかく言い換えた表現を5通りください。 状況別（貸切・ペット・早朝チェックイン）に使い分けられると助かります。 | H27: ✔ 答えの内容（時間・料金など）が実際と合っている ✔ 個人情報（お客様の名前・電話・メール・予約番号）は入れていない（A様のように置き換える） | I27: 私は{{宿の種類}}のフロント担当です。 電話でよく受ける質問への「対応メモ」を表にしてください。 よくある質問： 1. （例：ペットは一緒に泊まれますか） 2. （例：送迎はありますか、時間は） 3. （例：チェックインの最終は何時ですか） 4. （例：アレルギー対応はできますか） 5. （例：キャンセル料はいつから） 表の列：質問／まず答える一文／確認すべきこと／即答or保留 回答文は、お客様への言葉を想定した丁寧な表現で。
A28: 23 | B28: LEVEL 2｜AIを宿の仕事で使う | C28: 接客・フロント | D28: 館内案内をわかりやすくする。質問が減る案内文の整え方 | E28: 案内文の読みやすさ診断を頼む（文を差し替えて送る） | F28: =IF(①宿プロフィール!$C$12="はい",①宿プロフィール!$C$14&CHAR(10)&CHAR(10),"")&SUBSTITUTE(SUBSTITUTE(SUBSTITUTE(I28,"{{宿の種類}}",①宿プロフィール!$E$4),"{{立場}}",①宿プロフィール!$E$5),"{{客室数}}",①宿プロフィール!$E$6) -> 私は温泉旅館のスタッフです。 以下の館内案内文の「読みにくさ」を診断してください。 【案内文】 （ここに現在の案内文を貼り付け） 診断の観点： 1. 一文の長さ（目安：1文40字以内） 2. 難しい漢字や専門用語 3. 大事な情報（時間・場所）が最初に来ているか 4. 読み手の疑問に先回りしているか 診断結果を箇条書きで挙げたあと、 改善版の文面を150字程度で提案してください。 | G28: 改善版の文を「やさしい日本語」に書き換えてください。 日本語が十分わからない方にも伝わる表現で。 | H28: ✔ 掲示する前に、実際の場所・設備・ルールと合っているか確認する ✔ 個人情報（お客様の名前・電話・メール・予約番号）は入れていない（A様のように置き換える） | I28: 私は{{宿の種類}}のスタッフです。 以下の館内案内文の「読みにくさ」を診断してください。 【案内文】 （ここに現在の案内文を貼り付け） 診断の観点： 1. 一文の長さ（目安：1文40字以内） 2. 難しい漢字や専門用語 3. 大事な情報（時間・場所）が最初に来ているか 4. 読み手の疑問に先回りしているか 診断結果を箇条書きで挙げたあと、 改善版の文面を150字程度で提案してください。
A29: 24 | B29: LEVEL 2｜AIを宿の仕事で使う | C29: 接客・フロント | D29: よくある質問（FAQ）をAIと作る。電話を減らし、予約を増やす準備 | E29: FAQの回答文をまとめて作ってもらう（質問を差し替えて送る） | F29: =IF(①宿プロフィール!$C$12="はい",①宿プロフィール!$C$14&CHAR(10)&CHAR(10),"")&SUBSTITUTE(SUBSTITUTE(SUBSTITUTE(I29,"{{宿の種類}}",①宿プロフィール!$E$4),"{{立場}}",①宿プロフィール!$E$5),"{{客室数}}",①宿プロフィール!$E$6) -> 私は温泉旅館のWeb担当です。 お客様からよくある質問への回答文を作ってください。 【質問リスト】 1. （例：チェックイン・チェックアウトの時間は？） 2. （例：送迎はありますか？） 3. （例：食事のアレルギー対応は？） 4. （例：支払い方法は？クレジットカードは？） 5. （例：キャンセル料は？） （10問まで追加可） 条件： ・回答は「結論の1行」から始める（その後に補足） ・長さ：各80字程度 ・口調：丁寧で簡潔 ・不安を先回りして消す表現を使う | G29: 上記のFAQを踏まえて、 「まだ質問は来ていないが、予約前のお客様が不安に思っていそうなこと」を 3つ挙げてください。あわせて、その回答文案もお願いします。 | H29: ✔ 公開する前に内容が正しいか確認し、見直す日を決める ✔ 個人情報（お客様の名前・電話・メール・予約番号）は入れていない（A様のように置き換える） | I29: 私は{{宿の種類}}のWeb担当です。 お客様からよくある質問への回答文を作ってください。 【質問リスト】 1. （例：チェックイン・チェックアウトの時間は？） 2. （例：送迎はありますか？） 3. （例：食事のアレルギー対応は？） 4. （例：支払い方法は？クレジットカードは？） 5. （例：キャンセル料は？） （10問まで追加可） 条件： ・回答は「結論の1行」から始める（その後に補足） ・長さ：各80字程度 ・口調：丁寧で簡潔 ・不安を先回りして消す表現を使う
A30: 25 | B30: LEVEL 2｜AIを宿の仕事で使う | C30: 接客・フロント | D30: 外国人のお客様への案内を考える。やさしい日本語と翻訳の段取り | E30: 案内をやさしい日本語→3言語に展開してもらう（そのままコピーOK） | F30: =IF(①宿プロフィール!$C$12="はい",①宿プロフィール!$C$14&CHAR(10)&CHAR(10),"")&SUBSTITUTE(SUBSTITUTE(SUBSTITUTE(I30,"{{宿の種類}}",①宿プロフィール!$E$4),"{{立場}}",①宿プロフィール!$E$5),"{{客室数}}",①宿プロフィール!$E$6) -> 私は温泉旅館のスタッフです。 以下の館内案内を、外国人のお客様向けに整えてください。 【元の案内】 （ここに案内文を貼り付け。例：大浴場は15時から23時、朝は6時から9時までご利用いただけます。タオルはお部屋のものをお持ちください） お願い： 1. まず「やさしい日本語」に書き換える 2. 続けて英語・中国語（簡体字）・韓国語に翻訳 3. 文化的な注意が必要な点（入浴のマナーなど）があれば、 各言語版に短い補足を添える 4. 堅すぎず、宿らしい丁寧さのある表現で | G30: フロントでの簡単な接客英語フレーズを10本教えてください。 場面は「チェックイン手続き」「部屋の説明」「朝食時間の案内」「チェックアウト」。 各フレーズに日本語と、言い換え表現も添えてください。 | H30: ✔ 火災・避難・緊急連絡・料金・禁止事項などの翻訳は、AIだけで掲示しない。分かる人・専門家に確認してもらう ✔ 言語ごとに、実際に通じるか確かめる ✔ 個人情報（お客様の名前・電話・メール・予約番号）は入れていない（A様のように置き換える） | I30: 私は{{宿の種類}}のスタッフです。 以下の館内案内を、外国人のお客様向けに整えてください。 【元の案内】 （ここに案内文を貼り付け。例：大浴場は15時から23時、朝は6時から9時までご利用いただけます。タオルはお部屋のものをお持ちください） お願い： 1. まず「やさしい日本語」に書き換える 2. 続けて英語・中国語（簡体字）・韓国語に翻訳 3. 文化的な注意が必要な点（入浴のマナーなど）があれば、 各言語版に短い補足を添える 4. 堅すぎず、宿らしい丁寧さのある表現で
A31: 26 | B31: LEVEL 2｜AIを宿の仕事で使う | C31: OTA | D31: OTAの宿泊プランをAIと考える。まず全体を整理してから | E31: プラン全体の整理を頼む（そのままコピーOK） | F31: =IF(①宿プロフィール!$C$12="はい",①宿プロフィール!$C$14&CHAR(10)&CHAR(10),"")&SUBSTITUTE(SUBSTITUTE(SUBSTITUTE(I31,"{{宿の種類}}",①宿プロフィール!$E$4),"{{立場}}",①宿プロフィール!$E$5),"{{客室数}}",①宿プロフィール!$E$6) -> 私は客室12室の宿のOTA運用担当です。 以下のプラン一覧を、整理してください。 【プラン一覧（名称／動きの感覚）】 ・（例：スタンダード2食付き／一番売れる） ・（例：期間限定特典付き／時々売れる） ・（例：素泊まり格安／件数は多いが安い） ・（例：記念日向け／全く動かない） （実際のプランをすべて挙げる） お願い： 1. 各プランを「売れ筋」「利益筋」「呼び水」「休眠（動いていない）」に分類 2. このラインナップ全体の観察（偏りや隙間）を3点 3. 改善の優先度が高いと思われるプランを1つ、理由つきで まず、私の状況を確認するための質問があれば、3つまでお願いします。 | G31: 参考情報として、最近のレビューで多いコメントを要約します： （ここに、レビューの総評や最近のコメントの傾向を2〜3行。例：食事は高評価、風呂の老朽化の指摘、接客はまちまち、など） この傾向を踏まえると、 改善優先度が高いプランの考察は変わりますか？ | H31: ✔ 実データが必要な部分は、自分の数字で確かめる ✔ 個人情報（お客様の名前・電話・メール・予約番号）は入れていない（A様のように置き換える） | I31: 私は客室{{客室数}}室の宿のOTA運用担当です。 以下のプラン一覧を、整理してください。 【プラン一覧（名称／動きの感覚）】 ・（例：スタンダード2食付き／一番売れる） ・（例：期間限定特典付き／時々売れる） ・（例：素泊まり格安／件数は多いが安い） ・（例：記念日向け／全く動かない） （実際のプランをすべて挙げる） お願い： 1. 各プランを「売れ筋」「利益筋」「呼び水」「休眠（動いていない）」に分類 2. このラインナップ全体の観察（偏りや隙間）を3点 3. 改善の優先度が高いと思われるプランを1つ、理由つきで まず、私の状況を確認するための質問があれば、3つまでお願いします。
A32: 27 | B32: LEVEL 2｜AIを宿の仕事で使う | C32: OTA | D32: プラン名を改善する。検索され、選ばれる名前のルール | E32: プラン名の診断と改善案（対象プランを差し替えて送る） | F32: =IF(①宿プロフィール!$C$12="はい",①宿プロフィール!$C$14&CHAR(10)&CHAR(10),"")&SUBSTITUTE(SUBSTITUTE(SUBSTITUTE(I32,"{{宿の種類}}",①宿プロフィール!$E$4),"{{立場}}",①宿プロフィール!$E$5),"{{客室数}}",①宿プロフィール!$E$6) -> 私は宿のOTA担当です。 以下のプラン名の診断と改善案をお願いします。 【対象プラン】 1. （例：【直前割】お1人様歓迎！ビジネス・観光に最適◇バイキング2食付き） 2. （例：★リニューアル記念★源泉掛け流し露天付き客室プラン《部屋食》） （実際のプラン名を挙げる） 【各プランの内容の概要】 （例：1は平日のビジネス客向けで夕朝2食つき、2はグレードの高い客室で部屋食） お願い： 1. 各プラン名が「検索語」と「差別化語」に分解できているか診断 2. 改善案を各3パターン、20字以内で 3. 比較表（旧／新／狙い） 4. 記号（◆◇★）の使い方についてアドバイス | G32: 改善案から「A案」「B案」を2つに絞りました： A：（ここに案） B：（ここに案） 違いは言葉のニュアンスだけですが、 どちらがより「検索され、選ばれる」名前か、意見をください。 | H32: ✔ 「最安値」「日本一」など根拠のない言い切りが入っていない ✔ 文字数や表示は掲載先ごとに違う。実際の画面で確認する ✔ 個人情報（お客様の名前・電話・メール・予約番号）は入れていない（A様のように置き換える） | I32: 私は宿のOTA担当です。 以下のプラン名の診断と改善案をお願いします。 【対象プラン】 1. （例：【直前割】お1人様歓迎！ビジネス・観光に最適◇バイキング2食付き） 2. （例：★リニューアル記念★源泉掛け流し露天付き客室プラン《部屋食》） （実際のプラン名を挙げる） 【各プランの内容の概要】 （例：1は平日のビジネス客向けで夕朝2食つき、2はグレードの高い客室で部屋食） お願い： 1. 各プラン名が「検索語」と「差別化語」に分解できているか診断 2. 改善案を各3パターン、20字以内で 3. 比較表（旧／新／狙い） 4. 記号（◆◇★）の使い方についてアドバイス
A33: 28 | B33: LEVEL 2｜AIを宿の仕事で使う | C33: OTA | D33: プラン説明を改善する。読まれる文の「型」と注意点 | E33: プラン説明文の診断と改善（原文を差し替えて送る） | F33: =IF(①宿プロフィール!$C$12="はい",①宿プロフィール!$C$14&CHAR(10)&CHAR(10),"")&SUBSTITUTE(SUBSTITUTE(SUBSTITUTE(I33,"{{宿の種類}}",①宿プロフィール!$E$4),"{{立場}}",①宿プロフィール!$E$5),"{{客室数}}",①宿プロフィール!$E$6) -> 私は宿のOTA担当です。 以下のプラン説明文を改善してください。 【現在の文】 （ここに現在の説明文を貼り付け） 【プランの実際の内容】 （例：記念日向け。夕食時に記念写真を撮り翌朝プレゼント。ケーキ付き。2名1室） お願い： 1. 現在の文の良いところを3点指摘（そこは残します） 2. TIB（誰に／何が／どううれしい）の骨格で改善版を提示 3. 「条件・注意」は末尾に箇条書きで分離 4. 200字程度、口調はあたたかく | G33: この改善版を読んだお客様が、 「これにしよう」と思う理由を1行で挙げてください。 その文を、説明文の冒頭のキャッチとして使えますか？ | H33: ✔ 料金・特典・時間・条件が実際と合っている ✔ 「最安値」「日本一」など根拠のない言い切りが入っていない ✔ 個人情報（お客様の名前・電話・メール・予約番号）は入れていない（A様のように置き換える） | I33: 私は宿のOTA担当です。 以下のプラン説明文を改善してください。 【現在の文】 （ここに現在の説明文を貼り付け） 【プランの実際の内容】 （例：記念日向け。夕食時に記念写真を撮り翌朝プレゼント。ケーキ付き。2名1室） お願い： 1. 現在の文の良いところを3点指摘（そこは残します） 2. TIB（誰に／何が／どううれしい）の骨格で改善版を提示 3. 「条件・注意」は末尾に箇条書きで分離 4. 200字程度、口調はあたたかく
... A42: 37 | B42: LEVEL 2｜AIを宿の仕事で使う | C42: 企画・マーケティング | D42: 新しい宿泊プランを考える。思いつきで終わらせないAI企画術 | E42: 企画案の大量出し（条件を3回変えて送る） | F42: =IF(①宿プロフィール!$C$12="はい",①宿プロフィール!$C$14&CHAR(10)&CHAR(10),"")&SUBSTITUTE(SUBSTITUTE(SUBSTITUTE(I42,"{{宿の種類}}",①宿プロフィール!$E$4),"{{立場}}",①宿プロフィール!$E$5),"{{客室数}}",①宿プロフィール!$E$6) -> あなたは宿の企画ブレストの相手です。 「秋の平日プラン」について、10案考えてください。 条件A：ターゲット＝アクティブシニア（50〜70代夫婦）。 ※各案に「一言コンセプト」を添えて。 （10案出たら、続けて条件B・条件Cでお願いします） 条件B：ターゲット＝若い女性2〜3人組（20〜30代）。 条件C：テーマ＝「食」と「体験」の組み合わせ。 | G42: 採用候補「◯◯」について、 うまくいかない可能性を3点挙げてください。 それぞれに、簡単な対策を添えてください。 | H42: ✔ 実際に出せる企画か（人手・仕入れ・料金） ✔ 個人情報（お客様の名前・電話・メール・予約番号）は入れていない（A様のように置き換える） | I42: あなたは宿の企画ブレストの相手です。 「秋の平日プラン」について、10案考えてください。 条件A：ターゲット＝アクティブシニア（50〜70代夫婦）。 ※各案に「一言コンセプト」を添えて。 （10案出たら、続けて条件B・条件Cでお願いします） 条件B：ターゲット＝若い女性2〜3人組（20〜30代）。 条件C：テーマ＝「食」と「体験」の組み合わせ。
A43: 37 | B43: LEVEL 2｜AIを宿の仕事で使う | C43: 企画・マーケティング | D43: 新しい宿泊プランを考える。思いつきで終わらせないAI企画術 | E43: 気に入った1案を「調理」する（現実に落とす） | F43: =IF(①宿プロフィール!$C$12="はい",①宿プロフィール!$C$14&CHAR(10)&CHAR(10),"")&SUBSTITUTE(SUBSTITUTE(SUBSTITUTE(I43,"{{宿の種類}}",①宿プロフィール!$E$4),"{{立場}}",①宿プロフィール!$E$5),"{{客室数}}",①宿プロフィール!$E$6) -> さきほどの案の中の「◯◯」を採用候補にします。 この案を、私の宿（客室12室・家族4名とパート3名）で 実現するための「調理」をお願いします。 確認したいこと： 1. 必要な準備と概算コスト感 2. 現体制で回せるか、どこを工夫するか 3. 最初の小さな実験（トライアル版）の設計 4. 販売するOTAのプラン名案（3案） | H43: ✔ 実際に出せる企画か（人手・仕入れ・料金） ✔ 個人情報（お客様の名前・電話・メール・予約番号）は入れていない（A様のように置き換える） | I43: さきほどの案の中の「◯◯」を採用候補にします。 この案を、私の宿（客室12室・家族4名とパート3名）で 実現するための「調理」をお願いします。 確認したいこと： 1. 必要な準備と概算コスト感 2. 現体制で回せるか、どこを工夫するか 3. 最初の小さな実験（トライアル版）の設計 4. 販売するOTAのプラン名案（3案）
A44: 38 | B44: LEVEL 2｜AIを宿の仕事で使う | C44: 企画・マーケティング | D44: 閑散期の企画をAIと考える。お客様が来ない時期こそ、仕込みの時期 | E44: 閑散期の小さな企画を3案（そのままコピーOK） | F44: =IF(①宿プロフィール!$C$12="はい",①宿プロフィール!$C$14&CHAR(10)&CHAR(10),"")&SUBSTITUTE(SUBSTITUTE(SUBSTITUTE(I44,"{{宿の種類}}",①宿プロフィール!$E$4),"{{立場}}",①宿プロフィール!$E$5),"{{客室数}}",①宿プロフィール!$E$6) -> 私は客室12室の宿の企画担当です。 閑散期（◯◯月）の、小さくてすぐできる企画案を3つ出してください。 【宿の状況】 ・客室数：◯室／スタッフ：◯名／客単価：◯円前後／主な客層：◯◯ 【この時期の資産（箇条書き）】 （例：雪が多い 静か／この時期しか撮れない景色／農家の友人が野菜をくれる） 条件： ・少人数・低コスト・今月動ける ・「この時期だからこそ」の体験をテーマに ・各案に「ねらい／想定ターゲット」を1行添えて | G44: 以前宿泊してくれた方へ送る 「この時期だけのご案内」メールの文面を3案作ってください。 押し付けがましくなく、知人への便りのようなトーンで。 | H44: ✔ 実際に出せる企画か（人手・仕入れ・料金） ✔ 個人情報（お客様の名前・電話・メール・予約番号）は入れていない（A様のように置き換える） | I44: 私は客室{{客室数}}室の宿の企画担当です。 閑散期（◯◯月）の、小さくてすぐできる企画案を3つ出してください。 【宿の状況】 ・客室数：◯室／スタッフ：◯名／客単価：◯円前後／主な客層：◯◯ 【この時期の資産（箇条書き）】 （例：雪が多い 静か／この時期しか撮れない景色／農家の友人が野菜をくれる） 条件： ・少人数・低コスト・今月動ける ・「この時期だからこそ」の体験をテーマに ・各案に「ねらい／想定ターゲット」を1行添えて
A45: 39 | B45: LEVEL 2｜AIを宿の仕事で使う | C45: 企画・マーケティング | D45: 雨の日の宿泊プランを考える。悪天候も魅力に変える設計図 | E45: 雨の日限定の宿泊プラン案（そのままコピーOK） | F45: =IF(①宿プロフィール!$C$12="はい",①宿プロフィール!$C$14&CHAR(10)&CHAR(10),"")&SUBSTITUTE(SUBSTITUTE(SUBSTITUTE(I45,"{{宿の種類}}",①宿プロフィール!$E$4),"{{立場}}",①宿プロフィール!$E$5),"{{客室数}}",①宿プロフィール!$E$6) -> うちの宿で「雨の日限定プラン」を考えてください。 【うちの「雨に似合う要素」】 （例：ラウンジに本棚 部屋から川の眺め 雨音が聞こえる檜風呂） （実際の要素を挙げる） 条件： 1. 「雨だからできる体験」をコンセプトに 2. 雨天限定特典（例：ラウンジのコーヒー無料）を1つ 3. プラン名2案と説明文（150字程度） 4. 雨キャンセルを抑えるための一言案（予約確認メール用）も添えて | G45: 悪天候時の連絡テンプレートを3パターン作ってください。 A：雨予報時（体験の提案） B：台風等の注意喚起（誠実に、正確に） C：雪予報（アクセス情報） 使い分けの目安も添えてください。 | H45: ✔ 天候が荒れる日は、集客より安全が最優先 ✔ 個人情報（お客様の名前・電話・メール・予約番号）は入れていない（A様のように置き換える） | I45: うちの宿で「雨の日限定プラン」を考えてください。 【うちの「雨に似合う要素」】 （例：ラウンジに本棚 部屋から川の眺め 雨音が聞こえる檜風呂） （実際の要素を挙げる） 条件： 1. 「雨だからできる体験」をコンセプトに 2. 雨天限定特典（例：ラウンジのコーヒー無料）を1つ 3. プラン名2案と説明文（150字程度） 4. 雨キャンセルを抑えるための一言案（予約確認メール用）も添えて
A46: 40 | B46: LEVEL 2｜AIを宿の仕事で使う | C46: 企画・マーケティング | D46: SNS投稿をAIに手伝ってもらう。続けられる仕組みの作り方 | E46: 月間のSNSネタ一覧を作ってもらう（そのままコピーOK） | F46: =IF(①宿プロフィール!$C$12="はい",①宿プロフィール!$C$14&CHAR(10)&CHAR(10),"")&SUBSTITUTE(SUBSTITUTE(SUBSTITUTE(I46,"{{宿の種類}}",①宿プロフィール!$E$4),"{{立場}}",①宿プロフィール!$E$5),"{{客室数}}",①宿プロフィール!$E$6) -> 私は温泉旅館のSNS担当です。 来月4週分（1週3投稿）のSNSネタ案を12本出してください。 【3本の柱】 1. 今日の宿（料理・風景・スタッフの日常） 2. こんな過ごし方（提案・季節の楽しみ） 3. 知ってほしい話（小さなこだわり・歴史） お願い： ・各案に「柱の番号／写真イメージ／文面の冒頭（30字程度）」を添える ・季節は◯月 ・AIっぽい一般論（頑張ります等）は避け、宿の日常が見える視点で | G46: さきほどの文面を、以下の条件で書き直してください。 ・「絶景」「最高」「是非」のような大げさな言葉は使わない ・「寒い朝に、お湯が熱い」など、泥臭い日常の言葉で ・読み物ではなく、今日の記録として | H46: ✔ 投稿の内容が事実 ✔ 写真に写り込んだお客様がいない ✔ 個人情報（お客様の名前・電話・メール・予約番号）は入れていない（A様のように置き換える） | I46: 私は{{宿の種類}}のSNS担当です。 来月4週分（1週3投稿）のSNSネタ案を12本出してください。 【3本の柱】 1. 今日の宿（料理・風景・スタッフの日常） 2. こんな過ごし方（提案・季節の楽しみ） 3. 知ってほしい話（小さなこだわり・歴史） お願い： ・各案に「柱の番号／写真イメージ／文面の冒頭（30字程度）」を添える ・季節は◯月 ・AIっぽい一般論（頑張ります等）は避け、宿の日常が見える視点で
A47: 41 | B47: LEVEL 2｜AIを宿の仕事で使う | C47: 企画・マーケティング | D47: 地域の観光資源から新しい企画を考える。宿は地域の玄関 | E47: 地域資源と宿の組み合わせ案（そのままコピーOK） | F47: =IF(①宿プロフィール!$C$12="はい",①宿プロフィール!$C$14&CHAR(10)&CHAR(10),"")&SUBSTITUTE(SUBSTITUTE(SUBSTITUTE(I47,"{{宿の種類}}",①宿プロフィール!$E$4),"{{立場}}",①宿プロフィール!$E$5),"{{客室数}}",①宿プロフィール!$E$6) -> 私は山あいの小さな宿の担当です。 地域の資源を、宿の企画に活かしたいです。 【地域資源（箇条書き）】 （例：隣の農家 古い神社 鮎釣りの川 なにもない静かな夜） （実際のものを挙げる） お願い： 1. 資源と宿を組み合わせた企画案を5つ 2. 各案に「誰に／いつ（季節）／どんな価値があるか」を1行 3. 「まず小さく試せる案」を1つ、実行の手順添えで 4. 地域の人とどう関わるべきかの視点も添えて | G47: 資源「◯◯」の案内カードを作ってください。 ・タイトル／お客様への案内文（100字程度）／アクセス・注意点 ・手書きではなく、印刷して部屋に置ける完成版をイメージ | H47: ✔ 地域の情報（営業時間・料金）は、最新の公式情報で確認する ✔ 個人情報（お客様の名前・電話・メール・予約番号）は入れていない（A様のように置き換える） | I47: 私は山あいの小さな宿の担当です。 地域の資源を、宿の企画に活かしたいです。 【地域資源（箇条書き）】 （例：隣の農家 古い神社 鮎釣りの川 なにもない静かな夜） （実際のものを挙げる） お願い： 1. 資源と宿を組み合わせた企画案を5つ 2. 各案に「誰に／いつ（季節）／どんな価値があるか」を1行 3. 「まず小さく試せる案」を1つ、実行の手順添えで 4. 地域の人とどう関わるべきかの視点も添えて
A48: 42 | B48: LEVEL 2｜AIを宿の仕事で使う | C48: 仕事を楽にする | D48: 会議をAIに整理してもらう。メモと議事録から「決まったこと」だけ | E48: 会議のメモを整理してもらう（そのままコピーOK） | F48: =IF(①宿プロフィール!$C$12="はい",①宿プロフィール!$C$14&CHAR(10)&CHAR(10),"")&SUBSTITUTE(SUBSTITUTE(SUBSTITUTE(I48,"{{宿の種類}}",①宿プロフィール!$E$4),"{{立場}}",①宿プロフィール!$E$5),"{{客室数}}",①宿プロフィール!$E$6) -> 私は宿の打ち合わせの幹事です。 以下のメモを整理してください。 【打ち合わせメモ（乱雑そのまま）】 （ここに会議中や会議後のメモを貼る。箇条書き・乱文OK。 例：秋の平日プランするか／値段どうする／料理長に確認／SNSやるか／ 送迎バス検討／去年の宿題の確認→料金表 前田さん） お願い： 1. 「決定事項」「宿題（ToDo）」「棚上げ（今回決めなかった）」に分類 2. 宿題には「担当」「期限」の欄を添える 3. あいまいな部分は「要確認」と明示 4. 表形式で | G48: 議事録の簡易テンプレートを作ってください。 「日時／参加者／決定事項／宿題（担当・期限）／棚上げ」の5欄で、 紙1枚に収まるサイズ。 | H48: ✔ 決定事項・担当・期限が、会議の内容と合っている ✔ 個人情報（お客様の名前・電話・メール・予約番号）は入れていない（A様のように置き換える） | I48: 私は宿の打ち合わせの幹事です。 以下のメモを整理してください。 【打ち合わせメモ（乱雑そのまま）】 （ここに会議中や会議後のメモを貼る。箇条書き・乱文OK。 例：秋の平日プランするか／値段どうする／料理長に確認／SNSやるか／ 送迎バス検討／去年の宿題の確認→料金表 前田さん） お願い： 1. 「決定事項」「宿題（ToDo）」「棚上げ（今回決めなかった）」に分類 2. 宿題には「担当」「期限」の欄を添える 3. あいまいな部分は「要確認」と明示 4. 表形式で
...

Sheet 確認チェック
B1: AIの答えが出たら｜確認チェック
B2: AIは下書きと整理が得意です。でも、数字・事実・約束の確認と、最後の判断は人の仕事です。
B4: 場面 | C4: 確認すること
B5: いつでも共通 | C5: ✔ お客様の名前・電話・メール・予約番号などの個人情報や、社内の秘密を入れていない ✔ 数字・日付・料金・時間・お客様への約束を、自分で確かめた ✔ 送る前、載せる前に、最後まで自分で読んだ ✔ AIが「必ず」「絶対」と言い切っているところは、根拠を聞く
B6: お客様へのメール・口コミ返信 | C6: ✔ 宛名・日付・金額・チェックイン時間・予約内容が合っている ✔ 口コミ返信は公開される。お客様が特定できる情報（部屋・日付・人数・同伴者）を書かない ✔ 厳しい口コミへの返信は、急がず責任者にも見てもらう
B7: プラン名・説明文（OTAなど） | C7: ✔ 「最安値」「日本一」「No.1」「業界初」など、根拠のない言い切りを使っていない ✔ 料金・特典・期間・キャンセル条件が、管理画面の実際の内容と合っている ✔ 不安なときは、詳しい人や専門家に相談する
B8: 多言語の案内 | C8: ✔ 火災・避難・緊急連絡・料金・禁止事項などは、AIの翻訳だけで掲示しない ✔ 分かる人・専門家に確認してもらい、実際に通じるか確かめる
B9: 求人票・採用の文章 | C9: ✔ 給与・勤務時間・休日・勤務地・仕事内容が正確（法的に必要な項目は労働局やハローワークで確認） ✔ 年齢・性別を限定する表現（「若い方」「男性のみ」など）を使っていない
B10: 面接の質問 | C10: ✔ 家族構成・出身地・生活環境・宗教や思想・結婚や出産の予定など、仕事の適性と関係のない質問はしない ✔ 迷ったら、公的機関の「公正な採用選考」の案内を確認する
B11: 気持ちの整理・相談 | C11: ✔ AIは相談相手であって、専門家の代わりではない ✔ つらさが続く・眠れない日が続くときは、身近な人や専門家、公的な相談窓口へ
B12: 売上・経営の数字 | C12: ✔ AIが挙げた原因は「仮説」。実際の数字（売上・手数料・人件費など）で確かめる ✔ 価格・投資・雇用など重要な判断は、人が決める

Sheet ご利用について
B1: ご利用について・更新履歴
B3: 名称 | C3: AIと宿｜お願い文集
B4: 版 | C4: v1.0
B5: 作成日 | C5: 2026-10-08
B6: 内容の確認日 | C6: （公開前に記入してください）
B7: お願い文の数 | C7: 困りごと24件＋記事60本ぶん（65件）
B8: ご利用条件（案） | C8: 社内でのご利用は自由です。再配布・販売はご遠慮ください。※公開前に内容を決めて書き換えてください。
B9: ご注意 | C9: AIの答えは正確とは限りません。重要なことは、必ず人が確認してください。AIサービスの画面・機能・料金は変わることがあります。
B10: 更新履歴 | C10: 2026-10-08 v1.0 初版
